Workbook

Sheet Data input
T1: 1 | V1: 2 | X1: 3
A4: P.O.Box 31758-Dubai, UAE. Tel +971 4 3205363, Fax +971 4 3205373, e-mail: glab@eim.ae | T4: Vertically down | V4: Horizontal | X4: Vertically Up
A5: WORKSHEET FOR SURFACE HARDNESS TEST BY REBOUND HAMMER
A6: Information provided to the Laboratory: | S6: X | U6: X | W6: X
A7: Contractor | D7: : | E7: 0 | M7: Report No : | N7: GR- | S7: 20 | T7: 15 | U7: 20 | V7: 10 | W7: 20
A8: Client | D8: : | E8: 0 | M8: Report Date : | N8: 00/00/0000 | S8: 21 | T8: 16 | U8: 21 | V8: 11 | W8: 21
A9: Consultant | D9: : | E9: M/s. 0 | M9: Request No : | N9: GQ- | S9: 22 | T9: 18 | U9: 22 | V9: 12 | W9: 22
A10: Project | D10: : | E10: 0 | M10: Sample No : | N10: GS- | S10: 23 | T10: 19 | U10: 23 | V10: 14 | W10: 23
A11: Description of structure | D11: : | E11: Column | M11: Lab Project No | N11: LP- | S11: 24 | T11: 20 | U11: 24 | V11: 16 | W11: 24
A12: Type of concrete : | D12: : | E12: NG | M12: Date of test : | N12: 00/00/0000 | S12: 25 | T12: 22 | U12: 25 | V12: 17 | W12: 25 | X12: 10
A13: Date cast : | D13: : | E13: NG | M13: Tested by : | N13: JAL | S13: 26 | T13: 24 | U13: 26 | V13: 18 | W13: 26 | X13: 11
S14: 27 | T14: 28 | U14: 27 | V14: 20 | W14: 27 | X14: 13
S15: 28 | T15: 27 | U15: 28 | V15: 22 | W15: 28 | X15: 14
A16: Reference measurement | E16: : | F16: (before test) | S16: 29 | T16: 28 | U16: 29 | V16: 23 | W16: 29 | X16: 16
A17: Reference measurement | E17: : | F17: (after test) | S17: 30 | T17: 30 | U17: 30 | V17: 25 | W17: 30 | X17: 17
A18: Reference used | E18: : | F18: Compression Machine Platen for DTM- | S18: 31 | T18: 32 | U18: 31 | V18: 26 | W18: 31 | X18: 18
A19: Hammer equipment Id. | E19: : | F19: SRH-1 | S19: 32 | T19: 34 | U19: 32 | V19: 28 | W19: 32 | X19: 20
A20: Hammer type | E20: : | F20: ELE Normal type, range 10 to 70 N/mm2 | S20: 33 | T20: 35 | U20: 33 | V20: 30 | W20: 33 | X20: 22
A21: Correlated property | E21: : | F21: Compressive strength in N/mm2 | S21: 34 | T21: 37 | U21: 34 | V21: 32 | W21: 34 | X21: 24
A22: Source of correlation | E22: : | F22: Correlation curves of resistance to compression, provided by manufacturer | S22: 35 | T22: 39 | U22: 35 | V22: 33 | W22: 35 | X22: 25
A23: Type of surface | E23: : | F23: Rough(Dry) | S23: 36 | T23: 40 | U23: 36 | V23: 35 | W23: 36 | X23: 27
A24: Surface moisture condition | E24: : | F24: Normal | S24: 37 | T24: 42 | U24: 37 | V24: 37 | W24: 37 | X24: 29
A25: Direction of test | E25: : | F25: Horizontal | M25: 3 | S25: 38 | T25: 44 | U25: 38 | V25: 39 | W25: 38 | X25: 30
A26: Test positions | E26: : | F26: Evenly spaced along length of column each 16 no. readings on approx.3cm grid. | S26: 39 | T26: 46 | U26: 39 | V26: 40 | W26: 39 | X26: 32
A27: Note: N/A indicates information not applicable | S27: 40 | T27: 48 | U27: 40 | V27: 42 | W27: 40 | X27: 34
A28: Result | S28: 41 | T28: 50 | U28: 41 | V28: 44 | W28: 41 | X28: 36
A29: Total No of readings taken | F29: 16 | S29: 42 | T29: 52 | U29: 42 | V29: 46 | W29: 42 | X29: 38
A30: Test No. | B30: Test Location | C30: Rebound Hammer readings | K30: Mean | L30: Range | M30: Standard Deviation | N30: Coefficient of variation (%) | O30: Correlated Strength (N/mm2) | S30: 43 | T30: 54 | U30: 43 | V30: 48 | W30: 43 | X30: 40
A31: 1 | B31: Column-1 | C31: 31 | D31: 34 | E31: 33 | F31: 34 | G31: 32 | H31: 31 | I31: 35 | J31: 31 | K31: =ROUND(AVERAGE(C31:J32),1) -> 32.2 | L31: =MAX(C31:J32)-MIN(C31:J32) -> 4 | M31: =POWER(((C31-$K31)^2+(D31-$K31)^2+(E31-$K31)^2+(F31-$K31)^2+(G31-$K31)^2+(H31-$K31)^2+(I31-$K31)^2+(J31-$K31)^2+(C32-$K31)^2+(D32-$K31)^2+(E32-$K31)^2+(F32-$K31)^2+(G32-$K31)^2+(H32-$K31)^2+(I32-$K31)^2+(J32-$K31)^2)/($F$29-1),0.5) -> 1.3276546 | N31: =M31/K31*100 -> 4.1231508 | O31: 28 | Q31: 28 | S31: 44 | T31: 56 | U31: 44 | V31: 50 | W31: 44 | X31: 42
C32: 32 | D32: 31 | E32: 31 | F32: 31 | G32: 32 | H32: 33 | I32: 33 | J32: 31 | P32: =IF(M25=1,VLOOKUP(K31,S6:X42,2),IF(M25=2,VLOOKUP(K31,U6:X42,2),IF(M25=3,VLOOKUP(K31,W6:X42,2)))) -> 20 | S32: 45 | T32: 58 | U32: 45 | V32: 52 | W32: 45 | X32: 44
A33: 2 | B33: Column-2 | C33: 30 | D33: 32 | E33: 33 | F33: 35 | G33: 30 | H33: 34 | I33: 34 | J33: 32 | K33: =ROUND(AVERAGE(C33:J34),1) -> 32.8 | L33: =MAX(C33:J34)-MIN(C33:J34) -> 5 | M33: =POWER(((C33-$K33)^2+(D33-$K33)^2+(E33-$K33)^2+(F33-$K33)^2+(G33-$K33)^2+(H33-$K33)^2+(I33-$K33)^2+(J33-$K33)^2+(C34-$K33)^2+(D34-$K33)^2+(E34-$K33)^2+(F34-$K33)^2+(G34-$K33)^2+(H34-$K33)^2+(I34-$K33)^2+(J34-$K33)^2)/($F$29-1),0.5) -> 1.4841384 | N33: =M33/K33*100 -> 4.5248121 | O33: 28 | Q33: 28 | S33: 46 | T33: 60 | U33: 46 | V33: 54 | W33: 46 | X33: 46
C34: 33 | D34: 32 | E34: 32 | F34: 35 | G34: 34 | H34: 32 | I34: 33 | J34: 33 | S34: 47 | T34: 62 | U34: 47 | V34: 56 | W34: 47 | X34: 48
A35: 3 | B35: Column-3 | C35: 35 | D35: 36 | E35: 35 | F35: 37 | G35: 36 | H35: 36 | I35: 32 | J35: 35 | K35: =ROUND(AVERAGE(C35:J36),1) -> 35.7 | L35: =MAX(C35:J36)-MIN(C35:J36) -> 6 | M35: =POWER(((C35-$K35)^2+(D35-$K35)^2+(E35-$K35)^2+(F35-$K35)^2+(G35-$K35)^2+(H35-$K35)^2+(I35-$K35)^2+(J35-$K35)^2+(C36-$K35)^2+(D36-$K35)^2+(E36-$K35)^2+(F36-$K35)^2+(G36-$K35)^2+(H36-$K35)^2+(I36-$K35)^2+(J36-$K35)^2)/($F$29-1),0.5) -> 1.3525285 | N35: =M35/K35*100 -> 3.7885952 | O35: 34 | Q35: 34 | S35: 48 | T35: 64 | U35: 48 | V35: 58 | W35: 48 | X35: 50
C36: 35 | D36: 36 | E36: 35 | F36: 37 | G36: 35 | H36: 36 | I36: 38 | J36: 37 | S36: 49 | T36: 66 | U36: 49 | V36: 60 | W36: 49 | X36: 51
A37: 4 | B37: Column-4 | C37: 38 | D37: 36 | E37: 36 | F37: 37 | G37: 37 | H37: 39 | I37: 37 | J37: 36 | K37: =ROUND(AVERAGE(C37:J38),1) -> 36.9 | L37: =MAX(C37:J38)-MIN(C37:J38) -> 6 | M37: =POWER(((C37-$K37)^2+(D37-$K37)^2+(E37-$K37)^2+(F37-$K37)^2+(G37-$K37)^2+(H37-$K37)^2+(I37-$K37)^2+(J37-$K37)^2+(C38-$K37)^2+(D38-$K37)^2+(E38-$K37)^2+(F38-$K37)^2+(G38-$K37)^2+(H38-$K37)^2+(I38-$K37)^2+(J38-$K37)^2)/($F$29-1),0.5) -> 1.4085453 | N37: =M37/K37*100 -> 3.8171961 | O37: 36 | Q37: 36 | S37: 50 | T37: 68 | U37: 50 | V37: 62 | W37: 50 | X37: 53
C38: 36 | D38: 37 | E38: 38 | F38: 33 | G38: 38 | H38: 38 | I38: 38 | J38: 36 | S38: 51 | T38: 70 | U38: 51 | V38: 64 | W38: 51 | X38: 56
A39: 5 | B39: Column-5 | C39: 31 | D39: 32 | E39: 32 | F39: 34 | G39: 35 | H39: 34 | I39: 35 | J39: 34 | K39: =ROUND(AVERAGE(C39:J40),1) -> 33.3 | L39: =MAX(C39:J40)-MIN(C39:J40) -> 4 | M39: =POWER(((C39-$K39)^2+(D39-$K39)^2+(E39-$K39)^2+(F39-$K39)^2+(G39-$K39)^2+(H39-$K39)^2+(I39-$K39)^2+(J39-$K39)^2+(C40-$K39)^2+(D40-$K39)^2+(E40-$K39)^2+(F40-$K39)^2+(G40-$K39)^2+(H40-$K39)^2+(I40-$K39)^2+(J40-$K39)^2)/($F$29-1),0.5) -> 1.4385178 | N39: =M39/K39*100 -> 4.3198731 | O39: 30 | Q39: 30 | S39: 52 | U39: 52 | V39: 66 | W39: 52 | X39: 58
C40: 35 | D40: 31 | E40: 32 | F40: 33 | G40: 34 | H40: 35 | I40: 32 | J40: 33 | S40: 53 | U40: 53 | V40: 68 | W40: 53 | X40: 60
A41: 6 | B41: Column-6 | C41: 30 | D41: 31 | E41: 32 | F41: 30 | G41: 34 | H41: 35 | I41: 32 | J41: 33 | K41: =ROUND(AVERAGE(C41:J42),1) -> 32.4 | L41: =MAX(C41:J42)-MIN(C41:J42) -> 5 | M41: =POWER(((C41-$K41)^2+(D41-$K41)^2+(E41-$K41)^2+(F41-$K41)^2+(G41-$K41)^2+(H41-$K41)^2+(I41-$K41)^2+(J41-$K41)^2+(C42-$K41)^2+(D42-$K41)^2+(E42-$K41)^2+(F42-$K41)^2+(G42-$K41)^2+(H42-$K41)^2+(I42-$K41)^2+(J42-$K41)^2)/($F$29-1),0.5) -> 1.9314934 | N41: =M41/K41*100 -> 5.9613993 | O41: 28 | Q41: 28 | S41: 54 | U41: 54 | V41: 70 | W41: 54 | X41: 62
C42: 35 | D42: 35 | E42: 33 | F42: 30 | G42: 30 | H42: 31 | I42: 34 | J42: 34 | S42: 55 | U42: 55 | W42: 55 | X42: 64
...

Sheet Report
N5: P.O.Box 31758, Dubai - U.A.E. Tel : +971 4 3205363, Fax : +971 4 3205373, e-mail : glab@eim.ae
J6: REPORT ON SURFACE HARDNESS TESTING BY REBOUND HAMMER
A7: Contractor | D7: : | E7: ='Data input'!E7:L7 -> 0 | M7: Report No :
A8: Client | D8: : | E8: ='Data input'!E8:L8 -> 0 | M8: Report Date :
A9: Consultant | D9: : | M9: Request No :
A10: Project | D10: : | E10: ='Data input'!E10:L10 -> 0 | M10: Sample No :
A11: Plot No | D11: : | M11: Lab Project No :
A12: Location | D12: : | M12: Date of test :
A13: Description of structure | D13: : | E13: ='Data input'!E11:L11 -> Column | M13: Tested by :
A15: Test Result
A16: Hammer type | D16: : | E16: ='Data input'!F20 -> ELE Normal type, range 10 to 70 N/mm2 | M16: Spot located by : | N16: Consultant
A17: Reference Used | D17: : | E17: ='Data input'!F18 -> Compression Machine Platen for DTM- | M17: Type of concrete : | N17: ='Data input'!E12 -> NG
A18: Hammer equipment Id. | D18: : | E18: ='Data input'!F19 -> SRH-1 | M18: Date cast : | N18: ='Data input'!E13 -> NG
A19: Correlated property | D19: : | E19: ='Data input'!F21 -> Compressive strength in N/mm2 | M19: Type of surface : | N19: ='Data input'!F23 -> Rough(Dry)
A20: Surface moisture condition : | E20: ='Data input'!F24 -> Normal | M20: Direction of test : | N20: ='Data input'!F25 -> Horizontal
A21: Check test | D21: : | E21: (before test) / NT (after test), using NT
A22: Source of correlation | D22: : | E22: ='Data input'!F22 -> Correlation curves of resistance to compression, provided by manufacturer
A23: Test positions | D23: : | E23: ='Data input'!F26 -> Evenly spaced along length of column each 16 no. readings on approx.3cm grid.
A25: ID No. | B25: Location | C25: Rebound Measurements | K25: Range | L25: Std. Dev. | M25: Coeff. Of Var.% | N25: Mean | O25: Correlated Strength N/mm2
A26: ='Data input'!A31 -> 1 | B26: ='Data input'!B31 -> Column-1
A28: ='Data input'!A33 -> 2 | B28: ='Data input'!B33 -> Column-2
A30: ='Data input'!A35 -> 3 | B30: ='Data input'!B35 -> Column-3
A32: ='Data input'!A37 -> 4 | B32: ='Data input'!B37 -> Column-4
A34: ='Data input'!A39 -> 5 | B34: ='Data input'!B39 -> Column-5
A36: ='Data input'!A41 -> 6 | B36: ='Data input'!B41 -> Column-6
A38: ='Data input'!A43 -> 7 | B38: ='Data input'!B43 -> Column-7
A40: ='Data input'!A45 -> 8 | B40: ='Data input'!B45 -> Column-8
A42: Note: NG - Not Given
A43: Test Method | D43: :
A44: Test Method Variation | D44: : | E44: Nil
A45: Remarks | D45: : | E45: Nil
A46: Results relate only to the location tested
A47: This report shall not be reproduced except in full, without the written approval of the laboratory
A48: Any unauthorized amendment/correction will invalidate this test report
N49: Authorised Signatory

Sheet Sheet3
A4: P.O.Box 31758-Dubai, UAE. Tel +971 4 3205363, Fax +971 4 3205373, e-mail: glab@eim.ae
A5: WORKSHEET FOR SURFACE HARDNESS TEST BY REBOUND HAMMER
A6: Information provided to the Laboratory:
A7: Contractor | D7: : | M7: Report No :
A8: Client | D8: : | M8: Report Date :
A9: Consultant | D9: : | M9: Request No :
A10: Project | D10: : | M10: Sample No :
A11: Description of structure | D11: : | M11: Lab Project No
A12: Type of concrete : | D12: : | M12: Date of test :
A13: Date cast : | D13: : | M13: Tested by :
A15: Reference measurement | E15: : | F15: (before test)
A16: Reference measurement | E16: : | F16: (after test)
A17: Reference used | E17: : | F17: Compression Machine Platen for DTM-
A18: Hammer equipment Id. | E18: : | F18: SRH-1
A19: Hammer type | E19: : | F19: ELE Normal type, range 10 to 70 N/mm2
A20: Correlated property | E20: : | F20: Compressive strength in N/mm2
A21: Source of correlation | E21: : | F21: Correlation curves of resistance to compression, provided by manufacturer
A22: Type of surface | E22: : | F22: Rough(Dry)
A23: Surface moisture condition | E23: : | F23: Normal
A24: Direction of test | E24: : | F24: Horizontal/Vertical
A25: Test positions | E25: : | F25: Evenly spaced along length of column each 16 no. readings on approx.3cm grid.
A26: Note: N/A indicates information not applicable
A27: Result
A28: Test No. | B28: Test Location | C28: Rebound Hammer readings | K28: Mean | L28: Range | M28: Standard Deviation | N28: Coefficient of variation (%) | O28: Correlated Strength (N/mm2)
A45: Note: NG- Not Given
A46: Test method used | C46: : | D46: BS EN 12504-2:2021
A47: Test method variation | C47: : | D47: Reference anvil not used
A48: Remarks | C48: :
A50: Results relate only to the location tested
A51: This report shall not be reproduced except in full, without the written approval of the laboratory
A52: Any unauthorized amendment/correction will invalidate this test report
